<?xml version="1.0" encoding="utf-8"?>
<!-- This URDF was automatically created by SolidWorks to URDF Exporter! Originally created by Stephen Brawner (brawner@gmail.com) 
     Commit Version: 1.6.0-1-g15f4949  Build Version: 1.6.7594.29634
     For more information, please see http://wiki.ros.org/sw_urdf_exporter -->
<robot
  name="rover_delta">
  <link
    name="base_link">
    <inertial>
      <origin
        xyz="-0.0624120903932078 -0.0282640080894526 0.432729945535538"
        rpy="0 0 0" />
      <mass
        value="13.2207623449303" />
      <inertia
        ixx="0.158642716575027"
        ixy="8.60491381307464E-07"
        ixz="2.30923551046509E-06"
        iyy="0.129069389745107"
        iyz="8.60779421185298E-07"
        izz="0.162646112270567" />
    </inertial>
    <visual>
      <origin
        xyz="0 0 0"
        rpy="0 0 0" />
      <geometry>
        <mesh
          filename="package://rover_delta/meshes/base_link.STL" />
      </geometry>
      <material
        name="">
        <color
          rgba="0.792156862745098 0.819607843137255 0.933333333333333 1" />
      </material>
    </visual>
    <collision>
      <origin
        xyz="0 0 0"
        rpy="0 0 0" />
      <geometry>
        <mesh
          filename="package://rover_delta/meshes/base_link.STL" />
      </geometry>
    </collision>
  </link>
  <link
    name="linkbeforeleft">
    <inertial>
      <origin
        xyz="1.11022302462516E-15 0.0174382691873848 -1.38777878078145E-16"
        rpy="0 0 0" />
      <mass
        value="0.801171684247663" />
      <inertia
        ixx="0.00215127585319246"
        ixy="2.12856147476932E-18"
        ixz="9.23634044028535E-20"
        iyy="0.00415661128710577"
        iyz="1.43221597364142E-19"
        izz="0.00215127585319247" />
    </inertial>
    <visual>
      <origin
        xyz="0 0 0"
        rpy="0 0 0" />
      <geometry>
        <mesh
          filename="package://rover_delta/meshes/linkbeforeleft.STL" />
      </geometry>
      <material
        name="">
        <color
          rgba="0.792156862745098 0.819607843137255 0.933333333333333 1" />
      </material>
    </visual>
    <collision>
      <origin
        xyz="0 0 0"
        rpy="0 0 0" />
      <geometry>
        <mesh
          filename="package://rover_delta/meshes/linkbeforeleft.STL" />
      </geometry>
    </collision>
  </link>
  <joint
    name="beforeleft"
    type="continuous">
    <origin
      xyz="0.38651 0.33424 0.058047"
      rpy="0 0 0" />
    <parent
      link="base_link" />
    <child
      link="linkbeforeleft" />
    <axis
      xyz="0 1 0" />
  </joint>
  <link
    name="linkbeforeright">
    <inertial>
      <origin
        xyz="3.33066907387547E-16 -0.0174544176372946 -6.24500451351651E-17"
        rpy="0 0 0" />
      <mass
        value="0.801171684247668" />
      <inertia
        ixx="0.00215127585319247"
        ixy="5.238444935835E-18"
        ixz="1.88988361292109E-19"
        iyy="0.00415661128710578"
        iyz="1.9678293314073E-19"
        izz="0.00215127585319247" />
    </inertial>
    <visual>
      <origin
        xyz="0 0 0"
        rpy="0 0 0" />
      <geometry>
        <mesh
          filename="package://rover_delta/meshes/linkbeforeright.STL" />
      </geometry>
      <material
        name="">
        <color
          rgba="0.792156862745098 0.819607843137255 0.933333333333333 1" />
      </material>
    </visual>
    <collision>
      <origin
        xyz="0 0 0"
        rpy="0 0 0" />
      <geometry>
        <mesh
          filename="package://rover_delta/meshes/linkbeforeright.STL" />
      </geometry>
    </collision>
  </link>
  <joint
    name="beforeright"
    type="continuous">
    <origin
      xyz="0.386514478273016 -0.390763995039044 0.0580467119899354"
      rpy="0 0 0" />
    <parent
      link="base_link" />
    <child
      link="linkbeforeright" />
    <axis
      xyz="0 -1 0" />
  </joint>
  <link
    name="linkbehindleft">
    <inertial>
      <origin
        xyz="-2.08166817117217E-17 0.0174917373393941 0"
        rpy="0 0 0" />
      <mass
        value="0.782900413754047" />
      <inertia
        ixx="0.00213839505168217"
        ixy="3.75051852085778E-18"
        ixz="-3.29198464600314E-19"
        iyy="0.00415573217986098"
        iyz="1.7673695055494E-18"
        izz="0.00213839505168217" />
    </inertial>
    <visual>
      <origin
        xyz="0 0 0"
        rpy="0 0 0" />
      <geometry>
        <mesh
          filename="package://rover_delta/meshes/linkbehindleft.STL" />
      </geometry>
      <material
        name="">
        <color
          rgba="0.792156862745098 0.819607843137255 0.933333333333333 1" />
      </material>
    </visual>
    <collision>
      <origin
        xyz="0 0 0"
        rpy="0 0 0" />
      <geometry>
        <mesh
          filename="package://rover_delta/meshes/linkbehindleft.STL" />
      </geometry>
    </collision>
  </link>
  <joint
    name="behindleft"
    type="continuous">
    <origin
      xyz="-0.253487101216782 0.280536004960946 0.0680467119899032"
      rpy="0 0 0" />
    <parent
      link="base_link" />
    <child
      link="linkbehindleft" />
    <axis
      xyz="0 -1 0" />
  </joint>
  <link
    name="linkbehindright">
    <inertial>
      <origin
        xyz="-3.67761376907083E-16 -0.017508262660606 -4.16333634234434E-17"
        rpy="0 0 0" />
      <mass
        value="0.782900413754039" />
      <inertia
        ixx="0.00213839505168216"
        ixy="5.1374476691667E-17"
        ixz="-2.25682138981699E-19"
        iyy="0.00415573217986095"
        iyz="2.24461326828695E-18"
        izz="0.00213839505168216" />
    </inertial>
    <visual>
      <origin
        xyz="0 0 0"
        rpy="0 0 0" />
      <geometry>
        <mesh
          filename="package://rover_delta/meshes/linkbehindright.STL" />
      </geometry>
      <material
        name="">
        <color
          rgba="0.792156862745098 0.819607843137255 0.933333333333333 1" />
      </material>
    </visual>
    <collision>
      <origin
        xyz="0 0 0"
        rpy="0 0 0" />
      <geometry>
        <mesh
          filename="package://rover_delta/meshes/linkbehindright.STL" />
      </geometry>
    </collision>
  </link>
  <joint
    name="behindright"
    type="continuous">
    <origin
      xyz="-0.25348710121678 -0.337063995039051 0.0680467119899107"
      rpy="0 0 0" />
    <parent
      link="base_link" />
    <child
      link="linkbehindright" />
    <axis
      xyz="0 1 0" />
  </joint>
  <link
    name="linkquaytrai">
    <inertial>
      <origin
        xyz="0.0289647421166409 -0.00735915024312633 -0.121361098949186"
        rpy="0 0 0" />
      <mass
        value="1.07517565910656" />
      <inertia
        ixx="0.00302479560345683"
        ixy="-3.89341977730469E-09"
        ixz="0.000172470973111219"
        iyy="0.00503208142649592"
        iyz="9.32477680792686E-11"
        izz="0.002595533683283" />
    </inertial>
    <visual>
      <origin
        xyz="0 0 0"
        rpy="0 0 0" />
      <geometry>
        <mesh
          filename="package://rover_delta/meshes/linkquaytrai.STL" />
      </geometry>
      <material
        name="">
        <color
          rgba="0.792156862745098 0.819607843137255 0.933333333333333 1" />
      </material>
    </visual>
    <collision>
      <origin
        xyz="0 0 0"
        rpy="0 0 0" />
      <geometry>
        <mesh
          filename="package://rover_delta/meshes/linkquaytrai.STL" />
      </geometry>
    </collision>
  </link>
  <joint
    name="quaytrai"
    type="continuous">
    <origin
      xyz="0.34825 0.35905 0.21175"
      rpy="0 0 0" />
    <parent
      link="base_link" />
    <child
      link="linkquaytrai" />
    <axis
      xyz="0 0 -1" />
    <limit
      lower="0"
      upper="0"
      effort="0"
      velocity="0" />
  </joint>
  <link
    name="linkquayphai">
    <inertial>
      <origin
        xyz="0.0342066835970145 3.39134724831602E-05 -0.137660690472721"
        rpy="0 0 0" />
      <mass
        value="1.07517574915818" />
      <inertia
        ixx="0.00302480093250994"
        ixy="-5.90797596289731E-10"
        ixz="0.000172475794559178"
        iyy="0.00503209382442131"
        iyz="-1.28293444073387E-09"
        izz="0.00259553223546296" />
    </inertial>
    <visual>
      <origin
        xyz="0 0 0"
        rpy="0 0 0" />
      <geometry>
        <mesh
          filename="package://rover_delta/meshes/linkquayphai.STL" />
      </geometry>
      <material
        name="">
        <color
          rgba="0.792156862745098 0.819607843137255 0.933333333333333 1" />
      </material>
    </visual>
    <collision>
      <origin
        xyz="0 0 0"
        rpy="0 0 0" />
      <geometry>
        <mesh
          filename="package://rover_delta/meshes/linkquayphai.STL" />
      </geometry>
    </collision>
  </link>
  <joint
    name="quayphai"
    type="continuous">
    <origin
      xyz="0.34301 -0.40826 0.22805"
      rpy="0 0 0" />
    <parent
      link="base_link" />
    <child
      link="linkquayphai" />
    <axis
      xyz="0 0 -1" />
    <limit
      lower="0"
      upper="0"
      effort="0"
      velocity="0" />
  </joint>
</robot>